INFO:werkzeug: * Running on http://127.0.0.1:5000/ (Press CTRL+C to quit)
ERROR:flask.app:Exception on /api/v1/class/1 [GET]
Traceback (most recent call last):
  File "/home/nurchulis/anaconda3/lib/python3.6/site-packages/pymysql/connections.py", line 583, in connect
    **kwargs)
  File "/home/nurchulis/anaconda3/lib/python3.6/socket.py", line 724, in create_connection
    raise err
  File "/home/nurchulis/anaconda3/lib/python3.6/socket.py", line 713, in create_connection
    sock.connect(sa)
ConnectionRefusedError: [Errno 111] Connection refused

During handling of the above exception, another exception occurred:

Traceback (most recent call last):
  File "/home/nurchulis/anaconda3/lib/python3.6/site-packages/flask/app.py", line 2292, in wsgi_app
    response = self.full_dispatch_request()
  File "/home/nurchulis/anaconda3/lib/python3.6/site-packages/flask/app.py", line 1815, in full_dispatch_request
    rv = self.handle_user_exception(e)
  File "/home/nurchulis/anaconda3/lib/python3.6/site-packages/flask/app.py", line 1718, in handle_user_exception
    reraise(exc_type, exc_value, tb)
  File "/home/nurchulis/anaconda3/lib/python3.6/site-packages/flask/_compat.py", line 35, in reraise
    raise value
  File "/home/nurchulis/anaconda3/lib/python3.6/site-packages/flask/app.py", line 1813, in full_dispatch_request
    rv = self.dispatch_request()
  File "/home/nurchulis/anaconda3/lib/python3.6/site-packages/flask/app.py", line 1799, in dispatch_request
    return self.view_functions[rule.endpoint](**req.view_args)
  File "api.py", line 173, in get_class
    conn = mysql.connect()
  File "/home/nurchulis/anaconda3/lib/python3.6/site-packages/flaskext/mysql.py", line 53, in connect
    return pymysql.connect(**self.connect_args)
  File "/home/nurchulis/anaconda3/lib/python3.6/site-packages/pymysql/__init__.py", line 94, in Connect
    return Connection(*args, **kwargs)
  File "/home/nurchulis/anaconda3/lib/python3.6/site-packages/pymysql/connections.py", line 325, in __init__
    self.connect()
  File "/home/nurchulis/anaconda3/lib/python3.6/site-packages/pymysql/connections.py", line 630, in connect
    raise exc
pymysql.err.OperationalError: (2003, "Can't connect to MySQL server on 'localhost' ([Errno 111] Connection refused)")
INFO:werkzeug:127.0.0.1 - - [01/Mar/2019 21:17:45] "GET /api/v1/class/1 HTTP/1.1" 500 -
INFO:werkzeug:127.0.0.1 - - [01/Mar/2019 21:18:21] "GET /api/v1/class/1 HTTP/1.1" 200 -
INFO:werkzeug:127.0.0.1 - - [01/Mar/2019 21:18:22] "GET /api/v1/class/1 HTTP/1.1" 200 -
INFO:werkzeug: * Running on http://127.0.0.1:5000/ (Press CTRL+C to quit)
INFO:werkzeug:127.0.0.1 - - [01/Mar/2019 21:18:27] "GET /api/v1/class/1 HTTP/1.1" 200 -
INFO:werkzeug:127.0.0.1 - - [01/Mar/2019 21:18:40] "GET /api/v1/class/1 HTTP/1.1" 200 -
INFO:werkzeug:127.0.0.1 - - [01/Mar/2019 21:19:07] "POST /api/v1/update/11 HTTP/1.1" 200 -
INFO:werkzeug:127.0.0.1 - - [01/Mar/2019 21:19:09] "POST /api/v1/update/11 HTTP/1.1" 200 -
