/home/nurchulis/Documents/Belajar/API/learning-API/api
/home/nurchulis/Documents/Belajar/API/learning-API/api
/home/nurchulis/Documents/Belajar/API/learning-API/api
/home/nurchulis/Documents/Belajar/API/learning-API/api
/home/nurchulis/Documents/Belajar/API/learning-API/api/uploads/
saving /home/nurchulis/Documents/Belajar/API/learning-API/api/uploads/pp.jpeg
/home/nurchulis/Documents/Belajar/API/learning-API/api
/home/nurchulis/Documents/Belajar/API/learning-API/api/uploads/
saving /home/nurchulis/Documents/Belajar/API/learning-API/api/uploads/pp.jpeg
/home/nurchulis/Documents/Belajar/API/learning-API/api
/home/nurchulis/Documents/Belajar/API/learning-API/api/uploads/
saving /home/nurchulis/Documents/Belajar/API/learning-API/api/uploads/pp.jpeg
/home/nurchulis/Documents/Belajar/API/learning-API/api
/home/nurchulis/Documents/Belajar/API/learning-API/api/uploads/
saving /home/nurchulis/Documents/Belajar/API/learning-API/api/uploads/pp.jpeg
Exception on /api/v1/update_foto/1 [POST]
Traceback (most recent call last):
  File "/home/nurchulis/anaconda3/lib/python3.6/site-packages/flask/app.py", line 2292, in wsgi_app
    response = self.full_dispatch_request()
  File "/home/nurchulis/anaconda3/lib/python3.6/site-packages/flask/app.py", line 1815, in full_dispatch_request
    rv = self.handle_user_exception(e)
  File "/home/nurchulis/anaconda3/lib/python3.6/site-packages/flask/app.py", line 1718, in handle_user_exception
    reraise(exc_type, exc_value, tb)
  File "/home/nurchulis/anaconda3/lib/python3.6/site-packages/flask/_compat.py", line 35, in reraise
    raise value
  File "/home/nurchulis/anaconda3/lib/python3.6/site-packages/flask/app.py", line 1813, in full_dispatch_request
    rv = self.dispatch_request()
  File "/home/nurchulis/anaconda3/lib/python3.6/site-packages/flask/app.py", line 1799, in dispatch_request
    return self.view_functions[rule.endpoint](**req.view_args)
  File "api.py", line 424, in api_root
    update_photo(int(id),avatar)
  File "api.py", line 432, in update_photo
    result = cursor.execute("UPDATE User SET avatar = %s WHERE id_user = %s",avatar,int(id))
TypeError: execute() takes from 2 to 3 positional arguments but 4 were given
/home/nurchulis/Documents/Belajar/API/learning-API/api
/home/nurchulis/Documents/Belajar/API/learning-API/api/uploads/
saving /home/nurchulis/Documents/Belajar/API/learning-API/api/uploads/pp.jpeg
/home/nurchulis/Documents/Belajar/API/learning-API/api
/home/nurchulis/Documents/Belajar/API/learning-API/api/uploads/
saving /home/nurchulis/Documents/Belajar/API/learning-API/api/uploads/pp.jpeg
/home/nurchulis/Documents/Belajar/API/learning-API/api
/home/nurchulis/Documents/Belajar/API/learning-API/api/uploads/
saving /home/nurchulis/Documents/Belajar/API/learning-API/api/uploads/pp.jpeg
Exception on /api/v1/update_foto/1 [POST]
Traceback (most recent call last):
  File "/home/nurchulis/anaconda3/lib/python3.6/site-packages/flask/app.py", line 2292, in wsgi_app
    response = self.full_dispatch_request()
  File "/home/nurchulis/anaconda3/lib/python3.6/site-packages/flask/app.py", line 1815, in full_dispatch_request
    rv = self.handle_user_exception(e)
  File "/home/nurchulis/anaconda3/lib/python3.6/site-packages/flask/app.py", line 1718, in handle_user_exception
    reraise(exc_type, exc_value, tb)
  File "/home/nurchulis/anaconda3/lib/python3.6/site-packages/flask/_compat.py", line 35, in reraise
    raise value
  File "/home/nurchulis/anaconda3/lib/python3.6/site-packages/flask/app.py", line 1813, in full_dispatch_request
    rv = self.dispatch_request()
  File "/home/nurchulis/anaconda3/lib/python3.6/site-packages/flask/app.py", line 1799, in dispatch_request
    return self.view_functions[rule.endpoint](**req.view_args)
  File "api.py", line 424, in api_root
    update_photo(int(id),foto)
  File "api.py", line 432, in update_photo
    result = cursor.execute("UPDATE User SET avatar = 'foto' WHERE id_user = %s",int(id),foto)
TypeError: execute() takes from 2 to 3 positional arguments but 4 were given
/home/nurchulis/Documents/Belajar/API/learning-API/api
/home/nurchulis/Documents/Belajar/API/learning-API/api/uploads/
saving /home/nurchulis/Documents/Belajar/API/learning-API/api/uploads/pp.jpeg
Exception on /api/v1/update_foto/1 [POST]
Traceback (most recent call last):
  File "/home/nurchulis/anaconda3/lib/python3.6/site-packages/flask/app.py", line 2292, in wsgi_app
    response = self.full_dispatch_request()
  File "/home/nurchulis/anaconda3/lib/python3.6/site-packages/flask/app.py", line 1815, in full_dispatch_request
    rv = self.handle_user_exception(e)
  File "/home/nurchulis/anaconda3/lib/python3.6/site-packages/flask/app.py", line 1718, in handle_user_exception
    reraise(exc_type, exc_value, tb)
  File "/home/nurchulis/anaconda3/lib/python3.6/site-packages/flask/_compat.py", line 35, in reraise
    raise value
  File "/home/nurchulis/anaconda3/lib/python3.6/site-packages/flask/app.py", line 1813, in full_dispatch_request
    rv = self.dispatch_request()
  File "/home/nurchulis/anaconda3/lib/python3.6/site-packages/flask/app.py", line 1799, in dispatch_request
    return self.view_functions[rule.endpoint](**req.view_args)
  File "api.py", line 424, in api_root
    update_photo(int(id),foto)
  File "api.py", line 432, in update_photo
    result = cursor.execute("UPDATE User SET avatar = 'foto' WHERE id_user = %s",str(avatar),int(id))
NameError: name 'avatar' is not defined
/home/nurchulis/Documents/Belajar/API/learning-API/api
/home/nurchulis/Documents/Belajar/API/learning-API/api/uploads/
saving /home/nurchulis/Documents/Belajar/API/learning-API/api/uploads/pp.jpeg
Exception on /api/v1/update_foto/1 [POST]
Traceback (most recent call last):
  File "/home/nurchulis/anaconda3/lib/python3.6/site-packages/flask/app.py", line 2292, in wsgi_app
    response = self.full_dispatch_request()
  File "/home/nurchulis/anaconda3/lib/python3.6/site-packages/flask/app.py", line 1815, in full_dispatch_request
    rv = self.handle_user_exception(e)
  File "/home/nurchulis/anaconda3/lib/python3.6/site-packages/flask/app.py", line 1718, in handle_user_exception
    reraise(exc_type, exc_value, tb)
  File "/home/nurchulis/anaconda3/lib/python3.6/site-packages/flask/_compat.py", line 35, in reraise
    raise value
  File "/home/nurchulis/anaconda3/lib/python3.6/site-packages/flask/app.py", line 1813, in full_dispatch_request
    rv = self.dispatch_request()
  File "/home/nurchulis/anaconda3/lib/python3.6/site-packages/flask/app.py", line 1799, in dispatch_request
    return self.view_functions[rule.endpoint](**req.view_args)
  File "api.py", line 424, in api_root
    update_photo(int(id),foto)
  File "api.py", line 432, in update_photo
    result = cursor.execute("UPDATE User SET avatar = 'foto' WHERE id_user = %s",str(foto),int(id))
TypeError: execute() takes from 2 to 3 positional arguments but 4 were given
/home/nurchulis/Documents/Belajar/API/learning-API/api
/home/nurchulis/Documents/Belajar/API/learning-API/api/uploads/
saving /home/nurchulis/Documents/Belajar/API/learning-API/api/uploads/pp.jpeg
Exception on /api/v1/update_foto/1 [POST]
Traceback (most recent call last):
  File "/home/nurchulis/anaconda3/lib/python3.6/site-packages/flask/app.py", line 2292, in wsgi_app
    response = self.full_dispatch_request()
  File "/home/nurchulis/anaconda3/lib/python3.6/site-packages/flask/app.py", line 1815, in full_dispatch_request
    rv = self.handle_user_exception(e)
  File "/home/nurchulis/anaconda3/lib/python3.6/site-packages/flask/app.py", line 1718, in handle_user_exception
    reraise(exc_type, exc_value, tb)
  File "/home/nurchulis/anaconda3/lib/python3.6/site-packages/flask/_compat.py", line 35, in reraise
    raise value
  File "/home/nurchulis/anaconda3/lib/python3.6/site-packages/flask/app.py", line 1813, in full_dispatch_request
    rv = self.dispatch_request()
  File "/home/nurchulis/anaconda3/lib/python3.6/site-packages/flask/app.py", line 1799, in dispatch_request
    return self.view_functions[rule.endpoint](**req.view_args)
  File "api.py", line 424, in api_root
    update_photo(int(id),foto)
  File "api.py", line 432, in update_photo
    result = cursor.execute("UPDATE User SET avatar = %s WHERE id_user = %s",str(foto),int(id))
TypeError: execute() takes from 2 to 3 positional arguments but 4 were given
/home/nurchulis/Documents/Belajar/API/learning-API/api
/home/nurchulis/Documents/Belajar/API/learning-API/api/uploads/
saving /home/nurchulis/Documents/Belajar/API/learning-API/api/uploads/pp.jpeg
/home/nurchulis/Documents/Belajar/API/learning-API/api
/home/nurchulis/Documents/Belajar/API/learning-API/api/uploads/
saving /home/nurchulis/Documents/Belajar/API/learning-API/api/uploads/pp.jpeg
/home/nurchulis/Documents/Belajar/API/learning-API/api
/home/nurchulis/Documents/Belajar/API/learning-API/api/uploads/
saving /home/nurchulis/Documents/Belajar/API/learning-API/api/uploads/WhatsApp_Image_2018-12-19_at_21.45.42.jpeg
/home/nurchulis/Documents/Belajar/API/learning-API/api
/home/nurchulis/Documents/Belajar/API/learning-API/api/uploads/
saving /home/nurchulis/Documents/Belajar/API/learning-API/api/uploads/pp.jpeg
Exception on /api/v1/class/1 [GET]
Traceback (most recent call last):
  File "/home/nurchulis/anaconda3/lib/python3.6/site-packages/pymysql/connections.py", line 583, in connect
    **kwargs)
  File "/home/nurchulis/anaconda3/lib/python3.6/socket.py", line 724, in create_connection
    raise err
  File "/home/nurchulis/anaconda3/lib/python3.6/socket.py", line 713, in create_connection
    sock.connect(sa)
ConnectionRefusedError: [Errno 111] Connection refused

During handling of the above exception, another exception occurred:

Traceback (most recent call last):
  File "/home/nurchulis/anaconda3/lib/python3.6/site-packages/flask/app.py", line 2292, in wsgi_app
    response = self.full_dispatch_request()
  File "/home/nurchulis/anaconda3/lib/python3.6/site-packages/flask/app.py", line 1815, in full_dispatch_request
    rv = self.handle_user_exception(e)
  File "/home/nurchulis/anaconda3/lib/python3.6/site-packages/flask/app.py", line 1718, in handle_user_exception
    reraise(exc_type, exc_value, tb)
  File "/home/nurchulis/anaconda3/lib/python3.6/site-packages/flask/_compat.py", line 35, in reraise
    raise value
  File "/home/nurchulis/anaconda3/lib/python3.6/site-packages/flask/app.py", line 1813, in full_dispatch_request
    rv = self.dispatch_request()
  File "/home/nurchulis/anaconda3/lib/python3.6/site-packages/flask/app.py", line 1799, in dispatch_request
    return self.view_functions[rule.endpoint](**req.view_args)
  File "api.py", line 173, in get_class
    conn = mysql.connect()
  File "/home/nurchulis/anaconda3/lib/python3.6/site-packages/flaskext/mysql.py", line 53, in connect
    return pymysql.connect(**self.connect_args)
  File "/home/nurchulis/anaconda3/lib/python3.6/site-packages/pymysql/__init__.py", line 94, in Connect
    return Connection(*args, **kwargs)
  File "/home/nurchulis/anaconda3/lib/python3.6/site-packages/pymysql/connections.py", line 325, in __init__
    self.connect()
  File "/home/nurchulis/anaconda3/lib/python3.6/site-packages/pymysql/connections.py", line 630, in connect
    raise exc
pymysql.err.OperationalError: (2003, "Can't connect to MySQL server on 'localhost' ([Errno 111] Connection refused)")
Exception on /api/v1/upload [GET]
Traceback (most recent call last):
  File "/home/nurchulis/anaconda3/lib/python3.6/site-packages/flask/app.py", line 2292, in wsgi_app
    response = self.full_dispatch_request()
  File "/home/nurchulis/anaconda3/lib/python3.6/site-packages/flask/app.py", line 1816, in full_dispatch_request
    return self.finalize_request(rv)
  File "/home/nurchulis/anaconda3/lib/python3.6/site-packages/flask/app.py", line 1831, in finalize_request
    response = self.make_response(rv)
  File "/home/nurchulis/anaconda3/lib/python3.6/site-packages/flask/app.py", line 1957, in make_response
    'The view function did not return a valid response. The'
TypeError: The view function did not return a valid response. The function either returned None or ended without a return statement.
Exception on /api/v1/upload [GET]
Traceback (most recent call last):
  File "/home/nurchulis/anaconda3/lib/python3.6/site-packages/flask/app.py", line 2292, in wsgi_app
    response = self.full_dispatch_request()
  File "/home/nurchulis/anaconda3/lib/python3.6/site-packages/flask/app.py", line 1816, in full_dispatch_request
    return self.finalize_request(rv)
  File "/home/nurchulis/anaconda3/lib/python3.6/site-packages/flask/app.py", line 1831, in finalize_request
    response = self.make_response(rv)
  File "/home/nurchulis/anaconda3/lib/python3.6/site-packages/flask/app.py", line 1957, in make_response
    'The view function did not return a valid response. The'
TypeError: The view function did not return a valid response. The function either returned None or ended without a return statement.
/home/nurchulis/Documents/Belajar/API/learning-API/api
/home/nurchulis/Documents/Belajar/API/learning-API/api/uploads/
saving /home/nurchulis/Documents/Belajar/API/learning-API/api/uploads/pp.jpeg
/home/nurchulis/Documents/Belajar/API/learning-API/api
/home/nurchulis/Documents/Belajar/API/learning-API/api/uploads/
saving /home/nurchulis/Documents/Belajar/API/learning-API/api/uploads/pp.jpeg
/home/nurchulis/Documents/Belajar/API/learning-API/api
/home/nurchulis/Documents/Belajar/API/learning-API/api/uploads/
saving /home/nurchulis/Documents/Belajar/API/learning-API/api/uploads/pp.jpeg
/home/nurchulis/Documents/Belajar/API/learning-API/api
/home/nurchulis/Documents/Belajar/API/learning-API/api/uploads/
saving /home/nurchulis/Documents/Belajar/API/learning-API/api/uploads/pp.jpeg
Exception on /api/v1/update_foto/1 [POST]
Traceback (most recent call last):
  File "/home/nurchulis/anaconda3/lib/python3.6/site-packages/flask/app.py", line 2292, in wsgi_app
    response = self.full_dispatch_request()
  File "/home/nurchulis/anaconda3/lib/python3.6/site-packages/flask/app.py", line 1815, in full_dispatch_request
    rv = self.handle_user_exception(e)
  File "/home/nurchulis/anaconda3/lib/python3.6/site-packages/flask/app.py", line 1718, in handle_user_exception
    reraise(exc_type, exc_value, tb)
  File "/home/nurchulis/anaconda3/lib/python3.6/site-packages/flask/_compat.py", line 35, in reraise
    raise value
  File "/home/nurchulis/anaconda3/lib/python3.6/site-packages/flask/app.py", line 1813, in full_dispatch_request
    rv = self.dispatch_request()
  File "/home/nurchulis/anaconda3/lib/python3.6/site-packages/flask/app.py", line 1799, in dispatch_request
    return self.view_functions[rule.endpoint](**req.view_args)
  File "api.py", line 422, in api_root
    unik=img.filename("s")
TypeError: 'str' object is not callable
/home/nurchulis/Documents/Belajar/API/learning-API/api
/home/nurchulis/Documents/Belajar/API/learning-API/api/uploads/
saving /home/nurchulis/Documents/Belajar/API/learning-API/api/uploads/pp.jpeg
/home/nurchulis/Documents/Belajar/API/learning-API/api
/home/nurchulis/Documents/Belajar/API/learning-API/api/uploads/
saving /home/nurchulis/Documents/Belajar/API/learning-API/api/uploads/pp.jpeg
/home/nurchulis/Documents/Belajar/API/learning-API/api
/home/nurchulis/Documents/Belajar/API/learning-API/api/uploads/
saving /home/nurchulis/Documents/Belajar/API/learning-API/api/uploads/pp.jpeg
Exception on /api/v1/update_foto/1 [POST]
Traceback (most recent call last):
  File "/home/nurchulis/anaconda3/lib/python3.6/site-packages/flask/app.py", line 2292, in wsgi_app
    response = self.full_dispatch_request()
  File "/home/nurchulis/anaconda3/lib/python3.6/site-packages/flask/app.py", line 1815, in full_dispatch_request
    rv = self.handle_user_exception(e)
  File "/home/nurchulis/anaconda3/lib/python3.6/site-packages/flask/app.py", line 1718, in handle_user_exception
    reraise(exc_type, exc_value, tb)
  File "/home/nurchulis/anaconda3/lib/python3.6/site-packages/flask/_compat.py", line 35, in reraise
    raise value
  File "/home/nurchulis/anaconda3/lib/python3.6/site-packages/flask/app.py", line 1813, in full_dispatch_request
    rv = self.dispatch_request()
  File "/home/nurchulis/anaconda3/lib/python3.6/site-packages/flask/app.py", line 1799, in dispatch_request
    return self.view_functions[rule.endpoint](**req.view_args)
  File "api.py", line 422, in api_root
    unik=+str("s")+img.filename
TypeError: bad operand type for unary +: 'str'
/home/nurchulis/Documents/Belajar/API/learning-API/api
/home/nurchulis/Documents/Belajar/API/learning-API/api/uploads/
saving /home/nurchulis/Documents/Belajar/API/learning-API/api/uploads/pp.jpeg
/home/nurchulis/Documents/Belajar/API/learning-API/api
/home/nurchulis/Documents/Belajar/API/learning-API/api/uploads/
saving /home/nurchulis/Documents/Belajar/API/learning-API/api/uploads/pp.jpeg
/home/nurchulis/Documents/Belajar/API/learning-API/api
/home/nurchulis/Documents/Belajar/API/learning-API/api/uploads/
saving /home/nurchulis/Documents/Belajar/API/learning-API/api/uploads/pp.jpeg
/home/nurchulis/Documents/Belajar/API/learning-API/api
/home/nurchulis/Documents/Belajar/API/learning-API/api/uploads/
saving /home/nurchulis/Documents/Belajar/API/learning-API/api/uploads/pp.jpeg
/home/nurchulis/Documents/Belajar/API/learning-API/api
/home/nurchulis/Documents/Belajar/API/learning-API/api/uploads/
saving /home/nurchulis/Documents/Belajar/API/learning-API/api/uploads/giphy-downsized-small.mp4
/home/nurchulis/Documents/Belajar/API/learning-API/api
/home/nurchulis/Documents/Belajar/API/learning-API/api/uploads/
saving /home/nurchulis/Documents/Belajar/API/learning-API/api/uploads/giphy-downsized-small.mp4
/home/nurchulis/Documents/Belajar/API/learning-API/api
/home/nurchulis/Documents/Belajar/API/learning-API/api/uploads/
saving /home/nurchulis/Documents/Belajar/API/learning-API/api/uploads/blank-page.jpg
/home/nurchulis/Documents/Belajar/API/learning-API/api
/home/nurchulis/Documents/Belajar/API/learning-API/api/uploads/
saving /home/nurchulis/Documents/Belajar/API/learning-API/api/uploads/blank-page.jpg
/home/nurchulis/Documents/Belajar/API/learning-API/api
/home/nurchulis/Documents/Belajar/API/learning-API/api/uploads/
saving /home/nurchulis/Documents/Belajar/API/learning-API/api/uploads/blank-page.jpg
Exception on /api/v1/update_foto/1 [POST]
Traceback (most recent call last):
  File "/home/nurchulis/anaconda3/lib/python3.6/site-packages/flask/app.py", line 2292, in wsgi_app
    response = self.full_dispatch_request()
  File "/home/nurchulis/anaconda3/lib/python3.6/site-packages/flask/app.py", line 1815, in full_dispatch_request
    rv = self.handle_user_exception(e)
  File "/home/nurchulis/anaconda3/lib/python3.6/site-packages/flask/app.py", line 1718, in handle_user_exception
    reraise(exc_type, exc_value, tb)
  File "/home/nurchulis/anaconda3/lib/python3.6/site-packages/flask/_compat.py", line 35, in reraise
    raise value
  File "/home/nurchulis/anaconda3/lib/python3.6/site-packages/flask/app.py", line 1813, in full_dispatch_request
    rv = self.dispatch_request()
  File "/home/nurchulis/anaconda3/lib/python3.6/site-packages/flask/app.py", line 1799, in dispatch_request
    return self.view_functions[rule.endpoint](**req.view_args)
  File "api.py", line 426, in api_root
    update_photo(int(id),foto)
NameError: name 'foto' is not defined
/home/nurchulis/Documents/Belajar/API/learning-API/api
/home/nurchulis/Documents/Belajar/API/learning-API/api/uploads/
saving /home/nurchulis/Documents/Belajar/API/learning-API/api/uploads/blank-page.jpg
/home/nurchulis/Documents/Belajar/API/learning-API/api
/home/nurchulis/Documents/Belajar/API/learning-API/api/uploads/
saving /home/nurchulis/Documents/Belajar/API/learning-API/api/uploads/blank-page.jpg
/home/nurchulis/Documents/Belajar/API/learning-API/api
/home/nurchulis/Documents/Belajar/API/learning-API/api/uploads/
saving /home/nurchulis/Documents/Belajar/API/learning-API/api/uploads/blank-page.jpg
/home/nurchulis/Documents/Belajar/API/learning-API/api
/home/nurchulis/Documents/Belajar/API/learning-API/api/uploads/
saving /home/nurchulis/Documents/Belajar/API/learning-API/api/uploads/blank-page.jpg
/home/nurchulis/Documents/Belajar/API/learning-API/api
/home/nurchulis/Documents/Belajar/API/learning-API/api/uploads/
saving /home/nurchulis/Documents/Belajar/API/learning-API/api/uploads/blank-page.jpg
/home/nurchulis/Documents/Belajar/API/learning-API/api
/home/nurchulis/Documents/Belajar/API/learning-API/api/uploads/
saving /home/nurchulis/Documents/Belajar/API/learning-API/api/uploads/blank-page.jpg
/home/nurchulis/Documents/Belajar/API/learning-API/api
/home/nurchulis/Documents/Belajar/API/learning-API/api/uploads/
saving /home/nurchulis/Documents/Belajar/API/learning-API/api/uploads/sblank-page.jpg
/home/nurchulis/Documents/Belajar/API/learning-API/api
/home/nurchulis/Documents/Belajar/API/learning-API/api/uploads/
saving /home/nurchulis/Documents/Belajar/API/learning-API/api/uploads/sblank-page.jpg
/home/nurchulis/Documents/Belajar/API/learning-API/api
/home/nurchulis/Documents/Belajar/API/learning-API/api/uploads/
saving /home/nurchulis/Documents/Belajar/API/learning-API/api/uploads/serwin-setiadi-84165563-5ba70ca357b6d8.jpg
/home/nurchulis/Documents/Belajar/API/learning-API/api
/home/nurchulis/Documents/Belajar/API/learning-API/api/uploads/
saving /home/nurchulis/Documents/Belajar/API/learning-API/api/uploads/spp.jpeg
/home/nurchulis/Documents/Belajar/API/learning-API/api
/home/nurchulis/Documents/Belajar/API/learning-API/api/uploads/
saving /home/nurchulis/Documents/Belajar/API/learning-API/api/uploads/spp.jpeg
Exception on /api/v1/update_foto/1 [POST]
Traceback (most recent call last):
  File "/home/nurchulis/anaconda3/lib/python3.6/site-packages/flask/app.py", line 2292, in wsgi_app
    response = self.full_dispatch_request()
  File "/home/nurchulis/anaconda3/lib/python3.6/site-packages/flask/app.py", line 1815, in full_dispatch_request
    rv = self.handle_user_exception(e)
  File "/home/nurchulis/anaconda3/lib/python3.6/site-packages/flask/app.py", line 1718, in handle_user_exception
    reraise(exc_type, exc_value, tb)
  File "/home/nurchulis/anaconda3/lib/python3.6/site-packages/flask/_compat.py", line 35, in reraise
    raise value
  File "/home/nurchulis/anaconda3/lib/python3.6/site-packages/flask/app.py", line 1813, in full_dispatch_request
    rv = self.dispatch_request()
  File "/home/nurchulis/anaconda3/lib/python3.6/site-packages/flask/app.py", line 1799, in dispatch_request
    return self.view_functions[rule.endpoint](**req.view_args)
  File "api.py", line 429, in api_root
    print(randomString(8))
NameError: name 'randomString' is not defined
/home/nurchulis/Documents/Belajar/API/learning-API/api
/home/nurchulis/Documents/Belajar/API/learning-API/api/uploads/
saving /home/nurchulis/Documents/Belajar/API/learning-API/api/uploads/spp.jpeg
/home/nurchulis/Documents/Belajar/API/learning-API/api
/home/nurchulis/Documents/Belajar/API/learning-API/api/uploads/
saving /home/nurchulis/Documents/Belajar/API/learning-API/api/uploads/spp.jpeg
/home/nurchulis/Documents/Belajar/API/learning-API/api
/home/nurchulis/Documents/Belajar/API/learning-API/api/uploads/
saving /home/nurchulis/Documents/Belajar/API/learning-API/api/uploads/spp.jpeg
/home/nurchulis/Documents/Belajar/API/learning-API/api
/home/nurchulis/Documents/Belajar/API/learning-API/api/uploads/
saving /home/nurchulis/Documents/Belajar/API/learning-API/api/uploads/spp.jpeg
/home/nurchulis/Documents/Belajar/API/learning-API/api
/home/nurchulis/Documents/Belajar/API/learning-API/api/uploads/
saving /home/nurchulis/Documents/Belajar/API/learning-API/api/uploads/spp.jpeg
/home/nurchulis/Documents/Belajar/API/learning-API/api
/home/nurchulis/Documents/Belajar/API/learning-API/api/uploads/
saving /home/nurchulis/Documents/Belajar/API/learning-API/api/uploads/spp.jpeg
/home/nurchulis/Documents/Belajar/API/learning-API/api
/home/nurchulis/Documents/Belajar/API/learning-API/api/uploads/
saving /home/nurchulis/Documents/Belajar/API/learning-API/api/uploads/spp.jpeg
/home/nurchulis/Documents/Belajar/API/learning-API/api
/home/nurchulis/Documents/Belajar/API/learning-API/api/uploads/
saving /home/nurchulis/Documents/Belajar/API/learning-API/api/uploads/islryohjnevwxmfzgpkbpp.jpeg
Exception on /api/v1/email/nura3609@gmail.com [GET]
Traceback (most recent call last):
  File "/home/nurchulis/anaconda3/lib/python3.6/site-packages/flask/app.py", line 2292, in wsgi_app
    response = self.full_dispatch_request()
  File "/home/nurchulis/anaconda3/lib/python3.6/site-packages/flask/app.py", line 1815, in full_dispatch_request
    rv = self.handle_user_exception(e)
  File "/home/nurchulis/anaconda3/lib/python3.6/site-packages/flask/app.py", line 1718, in handle_user_exception
    reraise(exc_type, exc_value, tb)
  File "/home/nurchulis/anaconda3/lib/python3.6/site-packages/flask/_compat.py", line 35, in reraise
    raise value
  File "/home/nurchulis/anaconda3/lib/python3.6/site-packages/flask/app.py", line 1813, in full_dispatch_request
    rv = self.dispatch_request()
  File "/home/nurchulis/anaconda3/lib/python3.6/site-packages/flask/app.py", line 1799, in dispatch_request
    return self.view_functions[rule.endpoint](**req.view_args)
TypeError: send_email() got an unexpected keyword argument 'email'
Exception on /api/v1/email/nura3609@gmail.com [GET]
Traceback (most recent call last):
  File "/home/nurchulis/anaconda3/lib/python3.6/site-packages/flask/app.py", line 2292, in wsgi_app
    response = self.full_dispatch_request()
  File "/home/nurchulis/anaconda3/lib/python3.6/site-packages/flask/app.py", line 1815, in full_dispatch_request
    rv = self.handle_user_exception(e)
  File "/home/nurchulis/anaconda3/lib/python3.6/site-packages/flask/app.py", line 1718, in handle_user_exception
    reraise(exc_type, exc_value, tb)
  File "/home/nurchulis/anaconda3/lib/python3.6/site-packages/flask/_compat.py", line 35, in reraise
    raise value
  File "/home/nurchulis/anaconda3/lib/python3.6/site-packages/flask/app.py", line 1813, in full_dispatch_request
    rv = self.dispatch_request()
  File "/home/nurchulis/anaconda3/lib/python3.6/site-packages/flask/app.py", line 1799, in dispatch_request
    return self.view_functions[rule.endpoint](**req.view_args)
  File "api.py", line 464, in send_email
    mail.send(msg)
  File "/home/nurchulis/anaconda3/lib/python3.6/site-packages/flask_mail.py", line 492, in send
    message.send(connection)
  File "/home/nurchulis/anaconda3/lib/python3.6/site-packages/flask_mail.py", line 427, in send
    connection.send(self)
  File "/home/nurchulis/anaconda3/lib/python3.6/site-packages/flask_mail.py", line 181, in send
    if message.has_bad_headers():
  File "/home/nurchulis/anaconda3/lib/python3.6/site-packages/flask_mail.py", line 400, in has_bad_headers
    headers = [self.sender, self.reply_to] + self.recipients
TypeError: can only concatenate list (not "str") to list
Exception on /api/v1/email/nura3609@gmail.com [GET]
Traceback (most recent call last):
  File "/home/nurchulis/anaconda3/lib/python3.6/site-packages/flask/app.py", line 2292, in wsgi_app
    response = self.full_dispatch_request()
  File "/home/nurchulis/anaconda3/lib/python3.6/site-packages/flask/app.py", line 1815, in full_dispatch_request
    rv = self.handle_user_exception(e)
  File "/home/nurchulis/anaconda3/lib/python3.6/site-packages/flask/app.py", line 1718, in handle_user_exception
    reraise(exc_type, exc_value, tb)
  File "/home/nurchulis/anaconda3/lib/python3.6/site-packages/flask/_compat.py", line 35, in reraise
    raise value
  File "/home/nurchulis/anaconda3/lib/python3.6/site-packages/flask/app.py", line 1813, in full_dispatch_request
    rv = self.dispatch_request()
  File "/home/nurchulis/anaconda3/lib/python3.6/site-packages/flask/app.py", line 1799, in dispatch_request
    return self.view_functions[rule.endpoint](**req.view_args)
  File "api.py", line 464, in send_email
    mail.send(msg)
  File "/home/nurchulis/anaconda3/lib/python3.6/site-packages/flask_mail.py", line 492, in send
    message.send(connection)
  File "/home/nurchulis/anaconda3/lib/python3.6/site-packages/flask_mail.py", line 427, in send
    connection.send(self)
  File "/home/nurchulis/anaconda3/lib/python3.6/site-packages/flask_mail.py", line 181, in send
    if message.has_bad_headers():
  File "/home/nurchulis/anaconda3/lib/python3.6/site-packages/flask_mail.py", line 400, in has_bad_headers
    headers = [self.sender, self.reply_to] + self.recipients
TypeError: can only concatenate list (not "str") to list
Exception on /api/v1/email/nura3609@gmail.com [GET]
Traceback (most recent call last):
  File "/home/nurchulis/anaconda3/lib/python3.6/site-packages/flask/app.py", line 2292, in wsgi_app
    response = self.full_dispatch_request()
  File "/home/nurchulis/anaconda3/lib/python3.6/site-packages/flask/app.py", line 1815, in full_dispatch_request
    rv = self.handle_user_exception(e)
  File "/home/nurchulis/anaconda3/lib/python3.6/site-packages/flask/app.py", line 1718, in handle_user_exception
    reraise(exc_type, exc_value, tb)
  File "/home/nurchulis/anaconda3/lib/python3.6/site-packages/flask/_compat.py", line 35, in reraise
    raise value
  File "/home/nurchulis/anaconda3/lib/python3.6/site-packages/flask/app.py", line 1813, in full_dispatch_request
    rv = self.dispatch_request()
  File "/home/nurchulis/anaconda3/lib/python3.6/site-packages/flask/app.py", line 1799, in dispatch_request
    return self.view_functions[rule.endpoint](**req.view_args)
  File "api.py", line 464, in send_email
    mail.send(msg)
  File "/home/nurchulis/anaconda3/lib/python3.6/site-packages/flask_mail.py", line 492, in send
    message.send(connection)
  File "/home/nurchulis/anaconda3/lib/python3.6/site-packages/flask_mail.py", line 427, in send
    connection.send(self)
  File "/home/nurchulis/anaconda3/lib/python3.6/site-packages/flask_mail.py", line 181, in send
    if message.has_bad_headers():
  File "/home/nurchulis/anaconda3/lib/python3.6/site-packages/flask_mail.py", line 400, in has_bad_headers
    headers = [self.sender, self.reply_to] + self.recipients
TypeError: can only concatenate list (not "str") to list
Exception on /api/v1/email/nura3609@gmail.com [GET]
Traceback (most recent call last):
  File "/home/nurchulis/anaconda3/lib/python3.6/site-packages/flask/app.py", line 2292, in wsgi_app
    response = self.full_dispatch_request()
  File "/home/nurchulis/anaconda3/lib/python3.6/site-packages/flask/app.py", line 1815, in full_dispatch_request
    rv = self.handle_user_exception(e)
  File "/home/nurchulis/anaconda3/lib/python3.6/site-packages/flask/app.py", line 1718, in handle_user_exception
    reraise(exc_type, exc_value, tb)
  File "/home/nurchulis/anaconda3/lib/python3.6/site-packages/flask/_compat.py", line 35, in reraise
    raise value
  File "/home/nurchulis/anaconda3/lib/python3.6/site-packages/flask/app.py", line 1813, in full_dispatch_request
    rv = self.dispatch_request()
  File "/home/nurchulis/anaconda3/lib/python3.6/site-packages/flask/app.py", line 1799, in dispatch_request
    return self.view_functions[rule.endpoint](**req.view_args)
  File "api.py", line 464, in send_email
    mail.send(msg)
  File "/home/nurchulis/anaconda3/lib/python3.6/site-packages/flask_mail.py", line 492, in send
    message.send(connection)
  File "/home/nurchulis/anaconda3/lib/python3.6/site-packages/flask_mail.py", line 427, in send
    connection.send(self)
  File "/home/nurchulis/anaconda3/lib/python3.6/site-packages/flask_mail.py", line 181, in send
    if message.has_bad_headers():
  File "/home/nurchulis/anaconda3/lib/python3.6/site-packages/flask_mail.py", line 400, in has_bad_headers
    headers = [self.sender, self.reply_to] + self.recipients
TypeError: can only concatenate list (not "str") to list
Exception on /api/v1/email/nura3609@gmail.com [GET]
Traceback (most recent call last):
  File "/home/nurchulis/anaconda3/lib/python3.6/site-packages/flask/app.py", line 2292, in wsgi_app
    response = self.full_dispatch_request()
  File "/home/nurchulis/anaconda3/lib/python3.6/site-packages/flask/app.py", line 1815, in full_dispatch_request
    rv = self.handle_user_exception(e)
  File "/home/nurchulis/anaconda3/lib/python3.6/site-packages/flask/app.py", line 1718, in handle_user_exception
    reraise(exc_type, exc_value, tb)
  File "/home/nurchulis/anaconda3/lib/python3.6/site-packages/flask/_compat.py", line 35, in reraise
    raise value
  File "/home/nurchulis/anaconda3/lib/python3.6/site-packages/flask/app.py", line 1813, in full_dispatch_request
    rv = self.dispatch_request()
  File "/home/nurchulis/anaconda3/lib/python3.6/site-packages/flask/app.py", line 1799, in dispatch_request
    return self.view_functions[rule.endpoint](**req.view_args)
  File "api.py", line 462, in send_email
    print (email_name =str(email))
TypeError: 'email_name' is an invalid keyword argument for this function
Exception on /api/v1/email/nura3609@gmail.com [GET]
Traceback (most recent call last):
  File "/home/nurchulis/anaconda3/lib/python3.6/site-packages/flask/app.py", line 2292, in wsgi_app
    response = self.full_dispatch_request()
  File "/home/nurchulis/anaconda3/lib/python3.6/site-packages/flask/app.py", line 1815, in full_dispatch_request
    rv = self.handle_user_exception(e)
  File "/home/nurchulis/anaconda3/lib/python3.6/site-packages/flask/app.py", line 1718, in handle_user_exception
    reraise(exc_type, exc_value, tb)
  File "/home/nurchulis/anaconda3/lib/python3.6/site-packages/flask/_compat.py", line 35, in reraise
    raise value
  File "/home/nurchulis/anaconda3/lib/python3.6/site-packages/flask/app.py", line 1813, in full_dispatch_request
    rv = self.dispatch_request()
  File "/home/nurchulis/anaconda3/lib/python3.6/site-packages/flask/app.py", line 1799, in dispatch_request
    return self.view_functions[rule.endpoint](**req.view_args)
  File "api.py", line 464, in send_email
    msg.body = "Hai ini Code aktivasi mu"+123
TypeError: must be str, not int
Exception on /api/v1/email/nura3609@gmail.com [GET]
Traceback (most recent call last):
  File "/home/nurchulis/anaconda3/lib/python3.6/site-packages/flask/app.py", line 2292, in wsgi_app
    response = self.full_dispatch_request()
  File "/home/nurchulis/anaconda3/lib/python3.6/site-packages/flask/app.py", line 1815, in full_dispatch_request
    rv = self.handle_user_exception(e)
  File "/home/nurchulis/anaconda3/lib/python3.6/site-packages/flask/app.py", line 1718, in handle_user_exception
    reraise(exc_type, exc_value, tb)
  File "/home/nurchulis/anaconda3/lib/python3.6/site-packages/flask/_compat.py", line 35, in reraise
    raise value
  File "/home/nurchulis/anaconda3/lib/python3.6/site-packages/flask/app.py", line 1813, in full_dispatch_request
    rv = self.dispatch_request()
  File "/home/nurchulis/anaconda3/lib/python3.6/site-packages/flask/app.py", line 1799, in dispatch_request
    return self.view_functions[rule.endpoint](**req.view_args)
  File "api.py", line 464, in send_email
    msg.body = "Hai ini Code aktivasi mu :<h1>"+int(123)+"</h1>"
TypeError: must be str, not int
Exception on /api/v1/email/nura3609@gmail.com [GET]
Traceback (most recent call last):
  File "/home/nurchulis/anaconda3/lib/python3.6/site-packages/flask/app.py", line 2292, in wsgi_app
    response = self.full_dispatch_request()
  File "/home/nurchulis/anaconda3/lib/python3.6/site-packages/flask/app.py", line 1815, in full_dispatch_request
    rv = self.handle_user_exception(e)
  File "/home/nurchulis/anaconda3/lib/python3.6/site-packages/flask/app.py", line 1718, in handle_user_exception
    reraise(exc_type, exc_value, tb)
  File "/home/nurchulis/anaconda3/lib/python3.6/site-packages/flask/_compat.py", line 35, in reraise
    raise value
  File "/home/nurchulis/anaconda3/lib/python3.6/site-packages/flask/app.py", line 1813, in full_dispatch_request
    rv = self.dispatch_request()
  File "/home/nurchulis/anaconda3/lib/python3.6/site-packages/flask/app.py", line 1799, in dispatch_request
    return self.view_functions[rule.endpoint](**req.view_args)
  File "api.py", line 464, in send_email
    msg.body = "Hai ini Code aktivasi mu :<h1>"+int(123)
TypeError: must be str, not int
Exception on /api/v1/email/nura3609@gmail.com [GET]
Traceback (most recent call last):
  File "/home/nurchulis/anaconda3/lib/python3.6/site-packages/flask/app.py", line 2292, in wsgi_app
    response = self.full_dispatch_request()
  File "/home/nurchulis/anaconda3/lib/python3.6/site-packages/flask/app.py", line 1815, in full_dispatch_request
    rv = self.handle_user_exception(e)
  File "/home/nurchulis/anaconda3/lib/python3.6/site-packages/flask/app.py", line 1718, in handle_user_exception
    reraise(exc_type, exc_value, tb)
  File "/home/nurchulis/anaconda3/lib/python3.6/site-packages/flask/_compat.py", line 35, in reraise
    raise value
  File "/home/nurchulis/anaconda3/lib/python3.6/site-packages/flask/app.py", line 1813, in full_dispatch_request
    rv = self.dispatch_request()
  File "/home/nurchulis/anaconda3/lib/python3.6/site-packages/flask/app.py", line 1799, in dispatch_request
    return self.view_functions[rule.endpoint](**req.view_args)
  File "api.py", line 465, in send_email
    set_activation(activation_code)
NameError: name 'set_activation' is not defined
Exception on /api/v1/email/nura3d609@gmail.com/1 [GET]
Traceback (most recent call last):
  File "/home/nurchulis/anaconda3/lib/python3.6/site-packages/flask/app.py", line 2292, in wsgi_app
    response = self.full_dispatch_request()
  File "/home/nurchulis/anaconda3/lib/python3.6/site-packages/flask/app.py", line 1815, in full_dispatch_request
    rv = self.handle_user_exception(e)
  File "/home/nurchulis/anaconda3/lib/python3.6/site-packages/flask/app.py", line 1718, in handle_user_exception
    reraise(exc_type, exc_value, tb)
  File "/home/nurchulis/anaconda3/lib/python3.6/site-packages/flask/_compat.py", line 35, in reraise
    raise value
  File "/home/nurchulis/anaconda3/lib/python3.6/site-packages/flask/app.py", line 1813, in full_dispatch_request
    rv = self.dispatch_request()
  File "/home/nurchulis/anaconda3/lib/python3.6/site-packages/flask/app.py", line 1799, in dispatch_request
    return self.view_functions[rule.endpoint](**req.view_args)
  File "api.py", line 467, in send_email
    set_activation(activation_code,id_user)
NameError: name 'activation_code' is not defined
Exception on /api/v1/email/nura3d609@gmail.com/1 [GET]
Traceback (most recent call last):
  File "/home/nurchulis/anaconda3/lib/python3.6/site-packages/pymysql/connections.py", line 583, in connect
    **kwargs)
  File "/home/nurchulis/anaconda3/lib/python3.6/socket.py", line 724, in create_connection
    raise err
  File "/home/nurchulis/anaconda3/lib/python3.6/socket.py", line 713, in create_connection
    sock.connect(sa)
ConnectionRefusedError: [Errno 111] Connection refused

During handling of the above exception, another exception occurred:

Traceback (most recent call last):
  File "/home/nurchulis/anaconda3/lib/python3.6/site-packages/flask/app.py", line 2292, in wsgi_app
    response = self.full_dispatch_request()
  File "/home/nurchulis/anaconda3/lib/python3.6/site-packages/flask/app.py", line 1815, in full_dispatch_request
    rv = self.handle_user_exception(e)
  File "/home/nurchulis/anaconda3/lib/python3.6/site-packages/flask/app.py", line 1718, in handle_user_exception
    reraise(exc_type, exc_value, tb)
  File "/home/nurchulis/anaconda3/lib/python3.6/site-packages/flask/_compat.py", line 35, in reraise
    raise value
  File "/home/nurchulis/anaconda3/lib/python3.6/site-packages/flask/app.py", line 1813, in full_dispatch_request
    rv = self.dispatch_request()
  File "/home/nurchulis/anaconda3/lib/python3.6/site-packages/flask/app.py", line 1799, in dispatch_request
    return self.view_functions[rule.endpoint](**req.view_args)
  File "api.py", line 467, in send_email
    set_activation(code_activation,id_user)
  File "api.py", line 474, in set_activation
    conn = mysql.connect()
  File "/home/nurchulis/anaconda3/lib/python3.6/site-packages/flaskext/mysql.py", line 53, in connect
    return pymysql.connect(**self.connect_args)
  File "/home/nurchulis/anaconda3/lib/python3.6/site-packages/pymysql/__init__.py", line 94, in Connect
    return Connection(*args, **kwargs)
  File "/home/nurchulis/anaconda3/lib/python3.6/site-packages/pymysql/connections.py", line 325, in __init__
    self.connect()
  File "/home/nurchulis/anaconda3/lib/python3.6/site-packages/pymysql/connections.py", line 630, in connect
    raise exc
pymysql.err.OperationalError: (2003, "Can't connect to MySQL server on 'localhost' ([Errno 111] Connection refused)")
Exception on /api/v1/verif/1/2678 [GET]
Traceback (most recent call last):
  File "/home/nurchulis/anaconda3/lib/python3.6/site-packages/flask/app.py", line 2292, in wsgi_app
    response = self.full_dispatch_request()
  File "/home/nurchulis/anaconda3/lib/python3.6/site-packages/flask/app.py", line 1815, in full_dispatch_request
    rv = self.handle_user_exception(e)
  File "/home/nurchulis/anaconda3/lib/python3.6/site-packages/flask/app.py", line 1718, in handle_user_exception
    reraise(exc_type, exc_value, tb)
  File "/home/nurchulis/anaconda3/lib/python3.6/site-packages/flask/_compat.py", line 35, in reraise
    raise value
  File "/home/nurchulis/anaconda3/lib/python3.6/site-packages/flask/app.py", line 1813, in full_dispatch_request
    rv = self.dispatch_request()
  File "/home/nurchulis/anaconda3/lib/python3.6/site-packages/flask/app.py", line 1799, in dispatch_request
    return self.view_functions[rule.endpoint](**req.view_args)
  File "api.py", line 495, in verif_account
    update_verifed(id_user)
  File "api.py", line 506, in update_verifed
    result = cursor.execute("UPDATE User SET verifed = int(1) WHERE id_user = %s",int(id_user))
  File "/home/nurchulis/anaconda3/lib/python3.6/site-packages/pymysql/cursors.py", line 170, in execute
    result = self._query(query)
  File "/home/nurchulis/anaconda3/lib/python3.6/site-packages/pymysql/cursors.py", line 328, in _query
    conn.query(q)
  File "/home/nurchulis/anaconda3/lib/python3.6/site-packages/pymysql/connections.py", line 517, in query
    self._affected_rows = self._read_query_result(unbuffered=unbuffered)
  File "/home/nurchulis/anaconda3/lib/python3.6/site-packages/pymysql/connections.py", line 732, in _read_query_result
    result.read()
  File "/home/nurchulis/anaconda3/lib/python3.6/site-packages/pymysql/connections.py", line 1075, in read
    first_packet = self.connection._read_packet()
  File "/home/nurchulis/anaconda3/lib/python3.6/site-packages/pymysql/connections.py", line 684, in _read_packet
    packet.check_error()
  File "/home/nurchulis/anaconda3/lib/python3.6/site-packages/pymysql/protocol.py", line 220, in check_error
    err.raise_mysql_exception(self._data)
  File "/home/nurchulis/anaconda3/lib/python3.6/site-packages/pymysql/err.py", line 109, in raise_mysql_exception
    raise errorclass(errno, errval)
pymysql.err.ProgrammingError: (1064, "You have an error in your SQL syntax; check the manual that corresponds to your MySQL server version for the right syntax to use near 'int(1) WHERE id_user = 1' at line 1")
/home/nurchulis/Documents/Belajar/API/learning-API/api
/home/nurchulis/Documents/Belajar/API/learning-API/api/uploads/
saving /home/nurchulis/Documents/Belajar/API/learning-API/api/uploads/mcibfnlwytdkxrupeqzspp.jpeg
